<?xml version="1.0"?>
<mujoco model="vr_m3_1">
  <compiler angle="radian" meshdir="assets"/>

  <default>
    <default class="vr_m3_1_visual">
      <geom contype="0" conaffinity="0" group="2" density="0"/>
    </default>
    <default class="vr_m3_1_collision">
      <geom group="3" rgba="0.9 0.9 0 1"/>
    </default>
  </default>

  <asset>
    <mesh name="pelvis" content_type="model/stl" file="pelvis.stl"/>
    <mesh name="right_hip_pitch_link" content_type="model/stl" file="right_hip_pitch_link.stl"/>
    <mesh name="right_hip_roll_link" content_type="model/stl" file="right_hip_roll_link.stl"/>
    <mesh name="right_hip_yaw_link" content_type="model/stl" file="right_hip_yaw_link.stl"/>
    <mesh name="right_knee_pitch_link" content_type="model/stl" file="right_knee_pitch_link.stl"/>
    <mesh name="right_ankle_pitch_link" content_type="model/stl" file="right_ankle_pitch_link.stl"/>
    <mesh name="right_ankle_roll_link" content_type="model/stl" file="right_ankle_roll_link.stl"/>
    <mesh name="left_hip_pitch_link" content_type="model/stl" file="left_hip_pitch_link.stl"/>
    <mesh name="left_hip_roll_link" content_type="model/stl" file="left_hip_roll_link.stl"/>
    <mesh name="left_hip_yaw_link" content_type="model/stl" file="left_hip_yaw_link.stl"/>
    <mesh name="left_knee_pitch_link" content_type="model/stl" file="left_knee_pitch_link.stl"/>
    <mesh name="left_ankle_pitch_link" content_type="model/stl" file="left_ankle_pitch_link.stl"/>
    <mesh name="left_ankle_roll_link" content_type="model/stl" file="left_ankle_roll_link.stl"/>
    <mesh name="waist_yaw_link" content_type="model/stl" file="waist_yaw_link.stl"/>
    <mesh name="right_shoulder_pitch_link" content_type="model/stl" file="right_shoulder_pitch_link.stl"/>
    <mesh name="right_shoulder_roll_link" content_type="model/stl" file="right_shoulder_roll_link.stl"/>
    <mesh name="right_shoulder_yaw_link" content_type="model/stl" file="right_shoulder_yaw_link.stl"/>
    <mesh name="right_elbow_pitch_link" content_type="model/stl" file="right_elbow_pitch_link.stl"/>
    <mesh name="right_wrist_yaw_link" content_type="model/stl" file="right_wrist_yaw_link.stl"/>
    <mesh name="right_wrist_roll_link" content_type="model/stl" file="right_wrist_roll_link.stl"/>
    <mesh name="right_wrist_pitch_link" content_type="model/stl" file="right_wrist_pitch_link.stl"/>
    <mesh name="left_shoulder_pitch_link" content_type="model/stl" file="left_shoulder_pitch_link.stl"/>
    <mesh name="left_shoulder_roll_link" content_type="model/stl" file="left_shoulder_roll_link.stl"/>
    <mesh name="left_shoulder_yaw_link" content_type="model/stl" file="left_shoulder_yaw_link.stl"/>
    <mesh name="left_elbow_pitch_link" content_type="model/stl" file="left_elbow_pitch_link.stl"/>
    <mesh name="left_wrist_yaw_link" content_type="model/stl" file="left_wrist_yaw_link.stl"/>
    <mesh name="left_wrist_roll_link" content_type="model/stl" file="left_wrist_roll_link.stl"/>
    <mesh name="left_wrist_pitch_link" content_type="model/stl" file="left_wrist_pitch_link.stl"/>
    <mesh name="head_yaw_link" content_type="model/stl" file="head_yaw_link.stl"/>
    <mesh name="head_pitch_link" content_type="model/stl" file="head_pitch_link.stl"/>
  </asset>

  <worldbody>
    <body name="pelvis">
      <inertial pos="0.000224 -0.000218 0.011034" quat="0.706820769 -0.017358994 -0.017145994 0.706971768" mass="6.43185" diaginertia="0.036025 0.0260816 0.0229004"/>
      <joint name="base_joint" type="free"/>
      <geom name="pelvis_visual_0" class="vr_m3_1_visual" quat="0.707106781 0 0 -0.707106781" type="mesh" rgba="0.752941 0.752941 0.752941 1" mesh="pelvis"/>
      <geom name="pelvis_collision_1" class="vr_m3_1_collision" size="0.088 0.026" pos="0 0 0.0373" quat="0 0.707106781 -0.707106781 0" type="capsule"/>
      <site name="imu" pos="0 0.00614 -0.02485" size="0.01"/>
      <body name="left_hip_pitch_link" pos="0 0.143944 -0.03857">
        <inertial pos="0.009731 -0.019644 -0.052452" quat="0.044931816 0.075202126 -0.97797234 0.189462066" mass="2.54318" diaginertia="0.00546777 0.00485599 0.00340124"/>
        <joint name="left_hip_pitch_joint" pos="0 0 0" axis="0 0.965929 -0.258808" limited="true" range="-2.617 2.617" actuatorfrclimited="true" actuatorfrcrange="-360 360"/>
        <geom name="left_hip_pitch_link_visual_0" class="vr_m3_1_visual" pos="0 0 0" quat="-0.430478098 0.560971128 -0.560971128 -0.430478098" type="mesh" rgba="0.752941 0.752941 0.752941 1" mesh="left_hip_pitch_link"/>
        <body name="left_hip_roll_link" pos="0 -0.0161056 -0.0601066">
          <inertial pos="0.003238 -0.0026 -0.039714" quat="-0.469569654 0.522145615 -0.578204574 0.415388694" mass="0.415313" diaginertia="0.00116178 0.000851104 0.000724118"/>
          <joint name="left_hip_roll_joint" pos="0 0 0" axis="1 0 0" limited="true" range="-0.785 2.094" actuatorfrclimited="true" actuatorfrcrange="-360 360"/>
          <geom name="left_hip_roll_link_visual_0" class="vr_m3_1_visual" quat="-0.5 0.5 -0.5 0.5" type="mesh" rgba="0.752941 0.752941 0.752941 1" mesh="left_hip_roll_link"/>
          <geom name="left_hip_roll_link_collision_1" class="vr_m3_1_collision" size="0.072 0.00114" pos="0.0037 0.0038 -0.019" quat="-0.707106781 0 0 0.707106781" type="capsule"/>
          <body name="left_hip_yaw_link" pos="0 0 -0.293399">
            <inertial pos="0.000887 0.002453 0.070811" quat="-0.680706964 0.004787 0.003675 0.732530961" mass="4.09062" diaginertia="0.033991 0.0338443 0.00407464"/>
            <joint name="left_hip_yaw_joint" pos="0 0 0" axis="0 0 1" limited="true" range="-2.617 2.617" actuatorfrclimited="true" actuatorfrcrange="-130 130"/>
            <geom name="left_hip_yaw_link_visual_0" class="vr_m3_1_visual" quat="0 0 0 1" type="mesh" rgba="0.752941 0.752941 0.752941 1" mesh="left_hip_yaw_link"/>
            <geom name="left_hip_yaw_link_collision_1" class="vr_m3_1_collision" size="0.053004 0.039571" pos="-0.0001 0.001 0.1079" quat="0 0 1 0" type="capsule"/>
            <body name="left_knee_pitch_link">
              <inertial pos="-0.005799 -0.000097 -0.198823" quat="0.011998998 0.870719862 0.491519922 0.010540998" mass="3.35573" diaginertia="0.0396614 0.0395063 0.00352228"/>
              <joint name="left_knee_pitch_joint" pos="0 0 0" axis="0 1 0" limited="true" range="-0.174 2.356" actuatorfrclimited="true" actuatorfrcrange="-360 360"/>
              <geom name="left_knee_pitch_link_visual_0" class="vr_m3_1_visual" pos="0 0 0" quat="0.5 -0.5 0.5 0.5" type="mesh" rgba="0.752941 0.752941 0.752941 1" mesh="left_knee_pitch_link"/>
              <geom name="left_knee_pitch_link_collision_1" class="vr_m3_1_collision" size="0.06053 0.089494" pos="-0.0114 0.0005 -0.265" quat="0.707106781 0 0 0.707106781" type="capsule"/>
              <geom name="left_knee_pitch_link_collision_2" class="vr_m3_1_collision" size="0.055 0.03 0.052" pos="0.038 0 -0.045" quat="0.5 -0.5 0.5 0.5" type="box"/>
              <body name="left_ankle_pitch_link" pos="0 0 -0.411">
                <inertial pos="0 0 -0.000068" quat="0.5 -0.5 0.5 0.5" mass="0.097508" diaginertia="0.000019 0.000015 0.000012"/>
                <joint name="left_ankle_pitch_joint" pos="0 0 0" axis="0 1 0" limited="true" range="-0.873 0.523" actuatorfrclimited="true" actuatorfrcrange="-120 120"/>
                <geom name="left_ankle_pitch_link_visual_0" class="vr_m3_1_visual" quat="0.5 -0.5 0.5 0.5" type="mesh" rgba="0.647059 0.619608 0.588235 1" mesh="left_ankle_pitch_link"/>
                <body name="left_ankle_roll_link">
                  <inertial pos="-0.002511 -0.000018 -0.027456" quat="0.493858244 0.495631244 0.438220216 0.564284278" mass="0.800167" diaginertia="0.00287425 0.00286248 0.000501262"/>
                  <joint name="left_ankle_roll_joint" pos="0 0 0" axis="1 0 0" limited="true" range="-0.262 0.262" actuatorfrclimited="true" actuatorfrcrange="-120 120"/>
                  <geom name="left_ankle_roll_link_visual_0" class="vr_m3_1_visual" quat="0.707106781 0 0.707106781 0" type="mesh" rgba="0.752941 0.752941 0.752941 1" mesh="left_ankle_roll_link"/>
                  <geom name="left_ankle_roll_link_collision_1" class="vr_m3_1_collision" size="0.005 0.02" pos="0.07 0.045 -0.0463" quat="0.707106781 0 0.707106781 0" type="capsule"/>
                  <geom name="left_ankle_roll_link_collision_2" class="vr_m3_1_collision" size="0.005 0.1" pos="0.02 0.035 -0.0463" quat="0.707106781 0 0.707106781 0" type="capsule"/>
                  <geom name="left_ankle_roll_link_collision_3" class="vr_m3_1_collision" size="0.005 0.113" pos="0.02 0.025 -0.0463" quat="0.707106781 0 0.707106781 0" type="capsule"/>
                  <geom name="left_ankle_roll_link_collision_4" class="vr_m3_1_collision" size="0.005 0.121" pos="0.021 0.015 -0.0463" quat="0.707106781 0 0.707106781 0" type="capsule"/>
                  <geom name="left_ankle_roll_link_collision_5" class="vr_m3_1_collision" size="0.005 0.127" pos="0.021 0.005 -0.0463" quat="0.707106781 0 0.707106781 0" type="capsule"/>
                  <geom name="left_ankle_roll_link_collision_6" class="vr_m3_1_collision" size="0.005 0.127" pos="0.021 -0.005 -0.0463" quat="0.707106781 0 0.707106781 0" type="capsule"/>
                  <geom name="left_ankle_roll_link_collision_7" class="vr_m3_1_collision" size="0.005 0.125" pos="0.021 -0.015 -0.0463" quat="0.707106781 0 0.707106781 0" type="capsule"/>
                  <geom name="left_ankle_roll_link_collision_8" class="vr_m3_1_collision" size="0.005 0.118" pos="0.021 -0.025 -0.0463" quat="0.707106781 0 0.707106781 0" type="capsule"/>
                  <geom name="left_ankle_roll_link_collision_9" class="vr_m3_1_collision" size="0.005 0.1" pos="0.019 -0.035 -0.0463" quat="0.707106781 0 0.707106781 0" type="capsule"/>
                  <geom name="left_ankle_roll_link_collision_10" class="vr_m3_1_collision" size="0.005 0.03" pos="0.07 -0.045 -0.0463" quat="0.707106781 0 0.707106781 0" type="capsule"/>
                  <site name="left_foot" pos="0.045 0 -0.0463" size="0.01"/>
                </body>
              </body>
            </body>
          </body>
        </body>
      </body>
      <body name="right_hip_pitch_link" pos="0 -0.143944 -0.03857">
        <inertial pos="0.009731 0.019644 -0.052452" quat="0.044931816 -0.075202126 -0.97797234 -0.189462066" mass="2.54318" diaginertia="0.00546777 0.00485599 0.00340124"/>
        <joint name="right_hip_pitch_joint" pos="0 0 0" axis="0 0.965929 0.258808" limited="true" range="-2.617 2.617" actuatorfrclimited="true" actuatorfrcrange="-360 360"/>
        <geom name="right_hip_pitch_link_visual_0" class="vr_m3_1_visual" pos="0 0 0" quat="-0.560971128 0.430478098 -0.430478098 -0.560971128" type="mesh" rgba="0.752941 0.752941 0.752941 1" mesh="right_hip_pitch_link"/>
        <body name="right_hip_roll_link" pos="0 0.0161056 -0.0601066">
          <inertial pos="0.003238 0.0026 -0.039714" quat="0.415388694 -0.578204574 0.522145615 -0.469569654" mass="0.415313" diaginertia="0.00116178 0.000851104 0.000724118"/>
          <joint name="right_hip_roll_joint" pos="0 0 0" axis="1 0 0" limited="true" range="-2.094 0.785" actuatorfrclimited="true" actuatorfrcrange="-360 360"/>
          <geom name="right_hip_roll_link_visual_0" class="vr_m3_1_visual" quat="0.5 -0.5 0.5 -0.5" type="mesh" rgba="0.752941 0.752941 0.752941 1" mesh="right_hip_roll_link"/>
          <geom name="right_hip_roll_link_collision_1" class="vr_m3_1_collision" size="0.072 0.00114" pos="0.0037 -0.0038 -0.019" quat="0.707106781 0 0 -0.707106781" type="capsule"/>
          <body name="right_hip_yaw_link" pos="0 0 -0.293399">
            <inertial pos="0.000887 -0.002453 0.070811" quat="0.732530961 0.003675 0.004787 -0.680706964" mass="4.09062" diaginertia="0.033991 0.0338443 0.00407464"/>
            <joint name="right_hip_yaw_joint" pos="0 0 0" axis="0 0 1" limited="true" range="-2.617 2.617" actuatorfrclimited="true" actuatorfrcrange="-130 130"/>
            <geom name="right_hip_yaw_link_visual_0" class="vr_m3_1_visual" quat="0 0 0 -1" type="mesh" rgba="0.752941 0.752941 0.752941 1" mesh="right_hip_yaw_link"/>
            <geom name="right_hip_yaw_link_collision_1" class="vr_m3_1_collision" size="0.053004 0.039571" pos="-0.0001 0.001 0.1079" quat="0 0 -1 0" type="capsule"/>
            <body name="right_knee_pitch_link">
              <inertial pos="-0.005799 0.000097 -0.198823" quat="-0.010540998 -0.491519922 -0.870719862 -0.011998998" mass="3.35573" diaginertia="0.0396614 0.0395063 0.00352228"/>
              <joint name="right_knee_pitch_joint" pos="0 0 0" axis="0 1 0" limited="true" range="-0.174 2.356" actuatorfrclimited="true" actuatorfrcrange="-360 360"/>
              <geom name="right_knee_pitch_link_visual_0" class="vr_m3_1_visual" pos="0 0 0" quat="-0.5 0.5 -0.5 -0.5" type="mesh" rgba="0.752941 0.752941 0.752941 1" mesh="right_knee_pitch_link"/>
              <geom name="right_knee_pitch_link_collision_1" class="vr_m3_1_collision" size="0.06053 0.089494" pos="-0.0114 0.0005 -0.265" quat="-0.707106781 0 0 -0.707106781" type="capsule"/>
              <geom name="right_knee_pitch_link_collision_2" class="vr_m3_1_collision" size="0.055 0.03 0.052" pos="0.038 0 -0.045" quat="-0.5 0.5 -0.5 -0.5" type="box"/>
              <body name="right_ankle_pitch_link" pos="0 0 -0.411">
                <inertial pos="0 0 -0.000068" quat="-0.5 0.5 -0.5 -0.5" mass="0.097508" diaginertia="0.000019 0.000015 0.000012"/>
                <joint name="right_ankle_pitch_joint" pos="0 0 0" axis="0 1 0" limited="true" range="-0.873 0.523" actuatorfrclimited="true" actuatorfrcrange="-120 120"/>
                <geom name="right_ankle_pitch_link_visual_0" class="vr_m3_1_visual" quat="-0.5 0.5 -0.5 -0.5" type="mesh" rgba="0.647059 0.619608 0.588235 1" mesh="right_ankle_pitch_link"/>
                <body name="right_ankle_roll_link">
                  <inertial pos="-0.002511 0.000018 -0.027456" quat="-0.564284278 -0.438220216 -0.495631244 -0.493858244" mass="0.800167" diaginertia="0.00287425 0.00286248 0.000501262"/>
                  <joint name="right_ankle_roll_joint" pos="0 0 0" axis="1 0 0" limited="true" range="-0.262 0.262" actuatorfrclimited="true" actuatorfrcrange="-120 120"/>
                  <geom name="right_ankle_roll_link_visual_0" class="vr_m3_1_visual" quat="-0.707106781 0 -0.707106781 0" type="mesh" rgba="0.752941 0.752941 0.752941 1" mesh="right_ankle_roll_link"/>
                  <geom name="right_ankle_roll_link_collision_1" class="vr_m3_1_collision" size="0.005 0.02" pos="0.07 -0.045 -0.0463" quat="-0.707106781 0 -0.707106781 0" type="capsule"/>
                  <geom name="right_ankle_roll_link_collision_2" class="vr_m3_1_collision" size="0.005 0.1" pos="0.02 -0.035 -0.0463" quat="-0.707106781 0 -0.707106781 0" type="capsule"/>
                  <geom name="right_ankle_roll_link_collision_3" class="vr_m3_1_collision" size="0.005 0.113" pos="0.02 -0.025 -0.0463" quat="-0.707106781 0 -0.707106781 0" type="capsule"/>
                  <geom name="right_ankle_roll_link_collision_4" class="vr_m3_1_collision" size="0.005 0.121" pos="0.021 -0.015 -0.0463" quat="-0.707106781 0 -0.707106781 0" type="capsule"/>
                  <geom name="right_ankle_roll_link_collision_5" class="vr_m3_1_collision" size="0.005 0.127" pos="0.021 -0.005 -0.0463" quat="-0.707106781 0 -0.707106781 0" type="capsule"/>
                  <geom name="right_ankle_roll_link_collision_6" class="vr_m3_1_collision" size="0.005 0.127" pos="0.021 0.005 -0.0463" quat="-0.707106781 0 -0.707106781 0" type="capsule"/>
                  <geom name="right_ankle_roll_link_collision_7" class="vr_m3_1_collision" size="0.005 0.125" pos="0.021 0.015 -0.0463" quat="-0.707106781 0 -0.707106781 0" type="capsule"/>
                  <geom name="right_ankle_roll_link_collision_8" class="vr_m3_1_collision" size="0.005 0.118" pos="0.021 0.025 -0.0463" quat="-0.707106781 0 -0.707106781 0" type="capsule"/>
                  <geom name="right_ankle_roll_link_collision_9" class="vr_m3_1_collision" size="0.005 0.1" pos="0.019 0.035 -0.0463" quat="-0.707106781 0 -0.707106781 0" type="capsule"/>
                  <geom name="right_ankle_roll_link_collision_10" class="vr_m3_1_collision" size="0.005 0.03" pos="0.07 0.045 -0.0463" quat="-0.707106781 0 -0.707106781 0" type="capsule"/>
                  <site name="right_foot" pos="0.045 0 -0.0463" size="0.01"/>
                </body>
              </body>
            </body>
          </body>
        </body>
      </body>
      <body name="waist_yaw_link" pos="0 0 0.420134">
        <inertial pos="-0.014262 -0.00057 -0.111953" quat="-0.004481998 -0.047050984 -0.013465995 0.998791662" mass="16.9444" diaginertia="0.291317 0.227092 0.15517"/>
        <joint name="waist_yaw_joint" pos="0 0 0" axis="0 0 1" limited="true" range="-3.14 3.14" actuatorfrclimited="true" actuatorfrcrange="-102 102"/>
        <geom name="waist_yaw_link_visual_0" class="vr_m3_1_visual" quat="0 0 0 1" type="mesh" rgba="0.752941 0.752941 0.752941 1" mesh="waist_yaw_link"/>
        <geom name="waist_yaw_link_collision_1" class="vr_m3_1_collision" size="0.119734 0.057854" pos="0 0 -0.0791" quat="0 0 0 1" type="capsule"/>
        <body name="left_shoulder_pitch_link" pos="0 0.174999 0">
          <inertial pos="-0.003686 -0.002234 0.000048" quat="0.666083375 -0.262223148 0.654044368 0.244536138" mass="1.69784" diaginertia="0.00144111 0.00132242 0.00131247"/>
          <joint name="left_shoulder_pitch_joint" pos="0 0 0" axis="0 1 0" limited="true" range="-3.14 1.57" actuatorfrclimited="true" actuatorfrcrange="-66 66"/>
          <geom name="left_shoulder_pitch_link_visual_0" class="vr_m3_1_visual" quat="0.5 -0.5 0.5 0.5" type="mesh" rgba="0.752941 0.752941 0.752941 1" mesh="left_shoulder_pitch_link"/>
          <body name="left_shoulder_roll_link">
            <inertial pos="-0.001956 0.000016 -0.094554" quat="0.704270246 -0.05804252 0.05721452 -0.705238247" mass="0.711117" diaginertia="0.001434 0.00132273 0.000499266"/>
            <joint name="left_shoulder_roll_joint" pos="0 0 0" axis="1 0 0" limited="true" range="0 2.356" actuatorfrclimited="true" actuatorfrcrange="-66 66"/>
            <geom name="left_shoulder_roll_link_visual_0" class="vr_m3_1_visual" quat="0.5 -0.5 0.5 -0.5" type="mesh" rgba="0.752941 0.752941 0.752941 1" mesh="left_shoulder_roll_link"/>
            <geom name="left_shoulder_roll_link_collision_1" class="vr_m3_1_collision" size="0.047 0.041674" pos="-0.0025 0 -0.044" quat="0.707106781 0 0 -0.707106781" type="capsule"/>
            <body name="left_shoulder_yaw_link" pos="0 0 -0.23">
              <inertial pos="-0.00202 0.010279 0.054483" quat="0.683549737 -0.146675943 -0.170735934 -0.694330732" mass="0.178642" diaginertia="0.000240218 0.000238132 0.0000876502"/>
              <joint name="left_shoulder_yaw_joint" pos="0 0 0" axis="0 0 1" limited="true" range="-2.79 2.79" actuatorfrclimited="true" actuatorfrcrange="-34 34"/>
              <geom name="left_shoulder_yaw_link_visual_0" class="vr_m3_1_visual" quat="0 0 0 -1" type="mesh" rgba="0.752941 0.752941 0.752941 1" mesh="left_shoulder_yaw_link"/>
              <geom name="left_shoulder_yaw_link_collision_1" class="vr_m3_1_collision" size="0.0333 0.00815" pos="-0.01 0 0.064" quat="0 0 -0.707106781 -0.707106781" type="capsule"/>
              <body name="left_elbow_pitch_link">
                <inertial pos="0.005432 -0.000905 0.000096" quat="0.712543592 -0.051436971 -0.6993976 -0.021882987" mass="0.623076" diaginertia="0.000470082 0.000441891 0.000355027"/>
                <joint name="left_elbow_pitch_joint" pos="0 0 0" axis="0 1 0" limited="true" range="-0.524 1.571" actuatorfrclimited="true" actuatorfrcrange="-34 34"/>
                <geom name="left_elbow_pitch_link_visual_0" class="vr_m3_1_visual" quat="0.5 -0.5 -0.5 -0.5" type="mesh" rgba="0.752941 0.752941 0.752941 1" mesh="left_elbow_pitch_link"/>
                <geom name="left_elbow_pitch_link_collision_1" class="vr_m3_1_collision" size="0.030637 0.010363" pos="0.01 -0.0084 -0.0152" quat="0.708802693 0.001700009 -0.705402695 -0.001700009" type="capsule"/>
                <body name="left_wrist_yaw_link" pos="0.172 0 0">
                  <inertial pos="-0.078084 -0.000027 0.003505" quat="0.565479919 -0.424537939 -0.424537939 0.565479919" mass="0.617133" diaginertia="0.000783 0.000720652 0.000224348"/>
                  <joint name="left_wrist_yaw_joint" pos="0 0 0" axis="-1 0 0" limited="true" range="-2.79 2.79" actuatorfrclimited="true" actuatorfrcrange="-11 11"/>
                  <geom name="left_wrist_yaw_link_visual_0" class="vr_m3_1_visual" quat="0.5 -0.5 -0.5 0.5" type="mesh" rgba="0.752941 0.752941 0.752941 1" mesh="left_wrist_yaw_link"/>
                  <geom name="left_wrist_yaw_link_collision_1" class="vr_m3_1_collision" size="0.036526 0.038452" pos="-0.0487 -0.0001 0.0018" quat="0.5 0.5 0.5 0.5" type="capsule"/>
                  <body name="left_wrist_roll_link">
                    <inertial pos="0.006191 0.007362 0.00506" quat="-0.027734003 0.541649055 -0.449548045 0.709756072" mass="0.568929" diaginertia="0.000374851 0.000323713 0.000137436"/>
                    <joint name="left_wrist_roll_joint" pos="0 0 0" axis="0 0 1" limited="true" range="-1.571 1.571" actuatorfrclimited="true" actuatorfrcrange="-11 11"/>
                    <geom name="left_wrist_roll_link_visual_0" class="vr_m3_1_visual" type="mesh" rgba="0.752941 0.752941 0.752941 1" mesh="left_wrist_roll_link"/>
                    <geom name="left_wrist_roll_link_collision_1" class="vr_m3_1_collision" size="0.028375 0.014756" pos="0.065 0.0001 -0.0002" quat="0.707106654 -0.707106654 -0.000600006 0" type="capsule"/>
                    <body name="left_wrist_pitch_link" pos="0.058 0 0">
                      <inertial pos="0.001735 0.008087 0.000151" quat="0.693519866 -0.137949973 0.693519866 0.137949973" mass="0.488406" diaginertia="0.000123 0.000120485 0.000103515"/>
                      <joint name="left_wrist_pitch_joint" pos="0 0 0" axis="0 1 0" limited="true" range="-1.571 1.571" actuatorfrclimited="true" actuatorfrcrange="-11 11"/>
                      <geom name="left_wrist_pitch_link_visual_0" class="vr_m3_1_visual" quat="0.707106781 -0.707106781 0 0" type="mesh" rgba="0.752941 0.752941 0.752941 1" mesh="left_wrist_pitch_link"/>
                    </body>
                  </body>
                </body>
              </body>
            </body>
          </body>
        </body>
        <body name="right_shoulder_pitch_link" pos="0 -0.175001 0">
          <inertial pos="-0.003686 0.002234 0.000048" quat="0.666083375 0.262223148 0.654044368 -0.244536138" mass="1.69784" diaginertia="0.00144111 0.00132242 0.00131247"/>
          <joint name="right_shoulder_pitch_joint" pos="0 0 0" axis="0 1 0" limited="true" range="-3.14 1.57" actuatorfrclimited="true" actuatorfrcrange="-66 66"/>
          <geom name="right_shoulder_pitch_link_visual_0" class="vr_m3_1_visual" quat="0.5 -0.5 0.5 0.5" type="mesh" rgba="0.752941 0.752941 0.752941 1" mesh="right_shoulder_pitch_link"/>
          <body name="right_shoulder_roll_link">
            <inertial pos="-0.001956 -0.000016 -0.094554" quat="0.705238247 -0.05721452 0.05804252 -0.704270246" mass="0.711117" diaginertia="0.001434 0.00132273 0.000499266"/>
            <joint name="right_shoulder_roll_joint" pos="0 0 0" axis="1 0 0" limited="true" range="-2.356 0" actuatorfrclimited="true" actuatorfrcrange="-66 66"/>
            <geom name="right_shoulder_roll_link_visual_0" class="vr_m3_1_visual" quat="0.5 -0.5 0.5 -0.5" type="mesh" rgba="0.752941 0.752941 0.752941 1" mesh="right_shoulder_roll_link"/>
            <geom name="right_shoulder_roll_link_collision_1" class="vr_m3_1_collision" size="0.047 0.041674" pos="-0.0025 0 -0.044" quat="0.707106781 0 0 -0.707106781" type="capsule"/>
            <body name="right_shoulder_yaw_link" pos="0 0 -0.23">
              <inertial pos="-0.00202 -0.010279 0.054483" quat="0.694330732 0.170735934 0.146675943 -0.683549737" mass="0.178642" diaginertia="0.000240218 0.000238132 0.0000876502"/>
              <joint name="right_shoulder_yaw_joint" pos="0 0 0" axis="0 0 1" limited="true" range="-2.79 2.79" actuatorfrclimited="true" actuatorfrcrange="-34 34"/>
              <geom name="right_shoulder_yaw_link_visual_0" class="vr_m3_1_visual" quat="0 0 0 -1" type="mesh" rgba="0.752941 0.752941 0.752941 1" mesh="right_shoulder_yaw_link"/>
              <geom name="right_shoulder_yaw_link_collision_1" class="vr_m3_1_collision" size="0.0333 0.00815" pos="-0.01 0 0.064" quat="0 0 -0.707106781 -0.707106781" type="capsule"/>
              <body name="right_elbow_pitch_link">
                <inertial pos="0.005432 0.000905 0.000096" quat="0.712543592 0.051436971 -0.6993976 0.021882987" mass="0.623076" diaginertia="0.000470082 0.000441891 0.000355027"/>
                <joint name="right_elbow_pitch_joint" pos="0 0 0" axis="0 1 0" limited="true" range="-0.524 1.571" actuatorfrclimited="true" actuatorfrcrange="-34 34"/>
                <geom name="right_elbow_pitch_link_visual_0" class="vr_m3_1_visual" quat="0.5 -0.5 -0.5 -0.5" type="mesh" rgba="0.752941 0.752941 0.752941 1" mesh="right_elbow_pitch_link"/>
                <geom name="right_elbow_pitch_link_collision_1" class="vr_m3_1_collision" size="0.030637 0.010363" pos="0.01 -0.0084 -0.0152" quat="0.708802693 0.001700009 -0.705402695 -0.001700009" type="capsule"/>
                <body name="right_wrist_yaw_link" pos="0.172 0 0">
                  <inertial pos="-0.078084 0.000027 0.003505" quat="0.565479919 -0.424537939 -0.424537939 0.565479919" mass="0.617133" diaginertia="0.000783 0.000720652 0.000224348"/>
                  <joint name="right_wrist_yaw_joint" pos="0 0 0" axis="-1 0 0" limited="true" range="-2.79 2.79" actuatorfrclimited="true" actuatorfrcrange="-11 11"/>
                  <geom name="right_wrist_yaw_link_visual_0" class="vr_m3_1_visual" quat="0.5 -0.5 -0.5 0.5" type="mesh" rgba="0.752941 0.752941 0.752941 1" mesh="right_wrist_yaw_link"/>
                  <geom name="right_wrist_yaw_link_collision_1" class="vr_m3_1_collision" size="0.036526 0.038452" pos="-0.0487 -0.0001 0.0018" quat="0.5 0.5 0.5 0.5" type="capsule"/>
                  <body name="right_wrist_roll_link">
                    <inertial pos="0.006191 -0.007362 0.00506" quat="0.027734003 0.541649055 0.449548045 0.709756072" mass="0.568929" diaginertia="0.000374851 0.000323713 0.000137436"/>
                    <joint name="right_wrist_roll_joint" pos="0 0 0" axis="0 0 1" limited="true" range="-1.571 1.571" actuatorfrclimited="true" actuatorfrcrange="-11 11"/>
                    <geom name="right_wrist_roll_link_visual_0" class="vr_m3_1_visual" type="mesh" rgba="0.752941 0.752941 0.752941 1" mesh="right_wrist_roll_link"/>
                    <geom name="right_wrist_roll_link_collision_1" class="vr_m3_1_collision" size="0.028375 0.014756" pos="0.065 0.0001 -0.0002" quat="0.707106654 -0.707106654 -0.000600006 0" type="capsule"/>
                    <body name="right_wrist_pitch_link" pos="0.058 0 0">
                      <inertial pos="0.001735 -0.008087 0.000151" quat="0.693519866 0.137949973 0.693519866 -0.137949973" mass="0.488406" diaginertia="0.000123 0.000120485 0.000103515"/>
                      <joint name="right_wrist_pitch_joint" pos="0 0 0" axis="0 1 0" limited="true" range="-1.571 1.571" actuatorfrclimited="true" actuatorfrcrange="-11 11"/>
                      <geom name="right_wrist_pitch_link_visual_0" class="vr_m3_1_visual" quat="0.707106781 -0.707106781 0 0" type="mesh" rgba="0.752941 0.752941 0.752941 1" mesh="right_wrist_pitch_link"/>
                    </body>
                  </body>
                </body>
              </body>
            </body>
          </body>
        </body>
        <body name="head_yaw_link" pos="0 -0.000001 0.218181">
          <inertial pos="-0.000376 0.00322 -0.060039" quat="-0.056880998 -0.007543 -0.078404997 0.995268964" mass="1.08127" diaginertia="0.00201431 0.00199457 0.000743125"/>
          <joint name="head_yaw_joint" pos="0 0 0" axis="0 0 1" limited="true" range="-0.01 0.01" actuatorfrclimited="true" actuatorfrcrange="-11 11"/>
          <geom name="head_yaw_link_visual_0" class="vr_m3_1_visual" quat="0 0 0 1" type="mesh" rgba="0.752941 0.752941 0.752941 1" mesh="head_yaw_link"/>
          <body name="head_pitch_link">
            <inertial pos="0.050533 -0.000653 0.00896" quat="-0.552588958 0.446930966 0.468171965 -0.525083961" mass="0.502756" diaginertia="0.00149931 0.00137191 0.00105978"/>
            <joint name="head_pitch_joint" pos="0 0 0" axis="0 1 0" limited="true" range="-0.01 0.01" actuatorfrclimited="true" actuatorfrcrange="-4.8 4.8"/>
            <geom name="head_pitch_link_visual_0" class="vr_m3_1_visual" pos="0 0 0" quat="0 0 0.707106781 0.707106781" type="mesh" rgba="0.752941 0.752941 0.752941 1" mesh="head_pitch_link"/>
            <geom name="head_pitch_link_collision_1" class="vr_m3_1_collision" size="0.10661 0.00366" pos="0.0174 0 0" quat="-0.707106781 0 0 -0.707106781" type="capsule"/>
          </body>
        </body>
      </body>
    </body>
  </worldbody>
</mujoco>
