<mujoco model="vr_h3_1">
  <compiler angle="radian" meshdir="assets"/>
  <size njmax="1024" nconmax="512"/>

  <default>
    <default class="vr_h3_1">
      <joint armature="0.1" damping="1" frictionloss="0.1"/>
    </default>
    <default class="vr_h3_1_visual">
      <geom contype="0" conaffinity="0" group="2"/>
    </default>
    <default class="vr_h3_1_collision">
      <geom group="3" rgba="0.9 0.9 0 1"/>
    </default>
  </default>

  <asset>
    <mesh name="pelvis" content_type="model/stl" file="pelvis.stl"/>
    <mesh name="left_hip_pitch_link" content_type="model/stl" file="left_hip_pitch_link.stl"/>
    <mesh name="left_hip_roll_link" content_type="model/stl" file="left_hip_roll_link.stl"/>
    <mesh name="left_hip_yaw_link" content_type="model/stl" file="left_hip_yaw_link.stl"/>
    <mesh name="left_knee_pitch_link" content_type="model/stl" file="left_knee_pitch_link.stl"/>
    <mesh name="left_ankle_pitch_link" content_type="model/stl" file="left_ankle_pitch_link.stl"/>
    <mesh name="left_ankle_roll_link" content_type="model/stl" file="left_ankle_roll_link.stl"/>
    <mesh name="right_hip_pitch_link" content_type="model/stl" file="right_hip_pitch_link.stl"/>
    <mesh name="right_hip_roll_link" content_type="model/stl" file="right_hip_roll_link.stl"/>
    <mesh name="right_hip_yaw_link" content_type="model/stl" file="right_hip_yaw_link.stl"/>
    <mesh name="right_knee_pitch_link" content_type="model/stl" file="right_knee_pitch_link.stl"/>
    <mesh name="right_ankle_pitch_link" content_type="model/stl" file="right_ankle_pitch_link.stl"/>
    <mesh name="right_ankle_roll_link" content_type="model/stl" file="right_ankle_roll_link.stl"/>
    <mesh name="waist_yaw_link" content_type="model/stl" file="waist_yaw_link.stl"/>
    <mesh name="waist_roll_link" content_type="model/stl" file="waist_roll_link.stl"/>
    <mesh name="left_shoulder_pitch_link" content_type="model/stl" file="left_shoulder_pitch_link.stl"/>
    <mesh name="left_shoulder_roll_link" content_type="model/stl" file="left_shoulder_roll_link.stl"/>
    <mesh name="left_shoulder_yaw_link" content_type="model/stl" file="left_shoulder_yaw_link.stl"/>
    <mesh name="left_elbow_pitch_link" content_type="model/stl" file="left_elbow_pitch_link.stl"/>
    <mesh name="left_wrist_yaw_link" content_type="model/stl" file="left_wrist_yaw_link.stl"/>
    <mesh name="left_wrist_roll_link" content_type="model/stl" file="left_wrist_roll_link.stl"/>
    <mesh name="left_wrist_pitch_link" content_type="model/stl" file="left_wrist_pitch_link.stl"/>
    <mesh name="right_shoulder_pitch_link" content_type="model/stl" file="right_shoulder_pitch_link.stl"/>
    <mesh name="right_shoulder_roll_link" content_type="model/stl" file="right_shoulder_roll_link.stl"/>
    <mesh name="right_shoulder_yaw_link" content_type="model/stl" file="right_shoulder_yaw_link.stl"/>
    <mesh name="right_elbow_pitch_link" content_type="model/stl" file="right_elbow_pitch_link.stl"/>
    <mesh name="right_wrist_yaw_link" content_type="model/stl" file="right_wrist_yaw_link.stl"/>
    <mesh name="right_wrist_roll_link" content_type="model/stl" file="right_wrist_roll_link.stl"/>
    <mesh name="right_wrist_pitch_link" content_type="model/stl" file="right_wrist_pitch_link.stl"/>
    <mesh name="head_yaw_link" content_type="model/stl" file="head_yaw_link.stl"/>
    <mesh name="head_pitch_link" content_type="model/stl" file="head_pitch_link.stl"/>
  </asset>

  <worldbody>
    <body name="pelvis" childclass="vr_h3_1" pos = "0.0 0.0 0.85">
      <inertial pos="0.00039 0.00001 0.02925" quat="0.503104 -0.496971 0.496759 -0.503127" mass="3.6444" diaginertia="0.0084252 0.0094913 0.0121679"/>
      <joint name="root" type="free"/>
      <geom name="pelvis_visual_0" class="vr_h3_1_visual" type="mesh" mesh="pelvis"/>
      <geom name="pelvis_collision_1" class="vr_h3_1_collision" size="0.0575 0.05 0.0625" pos="0 0 0.027502" type="box"/>
      <site name="imu" pos="-0.00614 0 -0.02485" size="0.01"/>
      <body name="left_hip_pitch_link" pos="0 0.13345 0">
        <inertial pos="-0.00237 -0.00815 0.00015" quat="0.707259 -0.704347 -0.0547786 -0.0260834" mass="3.46394" diaginertia="0.0050098 0.0056898 0.006817"/>
        <joint name="left_hip_pitch_joint" pos="0 0 0" axis="0 1 0" range="-1.571 0.436" actuatorfrcrange="-369 369"/>
        <geom name="left_hip_pitch_link_visual_0" class="vr_h3_1_visual" quat="0.5 -0.5 0.5 0.5" type="mesh" mesh="left_hip_pitch_link"/>
        <body name="left_hip_roll_link">
          <inertial pos="-0.05315 0.00019 -0.05534" quat="0.299386 0.300502 0.639759 -0.640916" mass="5.4108" diaginertia="0.0115051 0.0434191 0.0468964"/>
          <joint name="left_hip_roll_joint" pos="0 0 0" axis="1 0 0" range="-0.175 1.047" actuatorfrcrange="-369 369"/>
          <geom name="left_hip_roll_link_visual_0" class="vr_h3_1_visual" quat="0.5 0.5 0.5 0.5" type="mesh" mesh="left_hip_roll_link"/>
          <geom name="left_hip_roll_link_collision_1" class="vr_h3_1_collision" size="0.065701 0.094456 0.089701" pos="0 0 -0.074544" quat="0.5 0.5 0.5 0.5" type="box"/>
          <geom name="left_hip_roll_link_collision_2" class="vr_h3_1_collision" size="0.065701 0.065701 0.03" pos="-0.119701 0 -0.000506" quat="0.5 0.5 0.5 0.5" type="box"/>
          <body name="left_hip_yaw_link" pos="0 0 -0.163">
            <inertial pos="0.00114 0.00594 -0.16274" quat="-0.491997 0.499747 0.523649 0.483718" mass="4.22238" diaginertia="0.0064746 0.0187543 0.019897"/>
            <joint name="left_hip_yaw_joint" pos="0 0 0" axis="0 0 1" range="-0.785 0.785" actuatorfrcrange="-191 191"/>
            <geom name="left_hip_yaw_link_visual_0" class="vr_h3_1_visual" pos="0 0 -0.19" quat="0 0 0 1" type="mesh" mesh="left_hip_yaw_link"/>
            <geom name="left_hip_yaw_link_collision_1" class="vr_h3_1_collision" size="0.064107 0.064107 0.028465" pos="0 0 -0.04" quat="0 0 0 1" type="box"/>
            <body name="left_knee_pitch_link" pos="0 0 -0.19">
              <inertial pos="-0.0093 0.00077 -0.17313" quat="-0.0218302 0.710539 0.0180948 0.703086" mass="4.51562" diaginertia="0.0081351 0.0536579 0.0545146"/>
              <joint name="left_knee_pitch_joint" pos="0 0 0" axis="0 1 0" range="-0.175 2.094" actuatorfrcrange="-369 369"/>
              <geom name="left_knee_pitch_link_visual_0" class="vr_h3_1_visual" pos="0 0 0" quat="-0.5 0.5 0.5 0.5" type="mesh" mesh="left_knee_pitch_link"/>
              <geom name="left_knee_pitch_link_collision_1" class="vr_h3_1_collision" size="0.091441 0.055441 0.057441" pos="-0.008043 0 -0.031032" quat="-0.5 0.5 0.5 0.5" type="box"/>
              <geom name="left_knee_pitch_link_collision_2" class="vr_h3_1_collision" size="0.069441 0.069441 0.059441" pos="-0.018343 0 -0.191913" quat="-0.5 0.5 0.5 0.5" type="box"/>
              <geom name="left_knee_pitch_link_collision_3" class="vr_h3_1_collision" size="0.059441 0.050441 0.052441" pos="-0.002033 0 -0.320795" quat="-0.5 0.5 0.5 0.5" type="box"/>
              <body name="left_ankle_pitch_link" pos="0 0 -0.434">
                <inertial pos="-0.00032 0 -0.00762" quat="0.463154 -0.462223 0.534993 0.534435" mass="0.08624" diaginertia="0.0000132 0.0000165 0.0000179"/>
                <joint name="left_ankle_pitch_joint" pos="0 0 0" axis="0 1 0" range="-0.873 0.524" actuatorfrcrange="-140 140"/>
                <geom name="left_ankle_pitch_link_visual_0" class="vr_h3_1_visual" quat="-0.5 0.5 0.5 0.5" type="mesh" mesh="left_ankle_pitch_link"/>
                <body name="left_ankle_roll_link" pos="0 0 -0.014">
                  <inertial pos="0.05279 0.00065 -0.017" quat="-0.999729 -0.0043234 0.0181868 0.0138545" mass="1.15735" diaginertia="0.0010949 0.0054005 0.0059189"/>
                  <joint name="left_ankle_roll_joint" pos="0 0 0" axis="1 0 0" range="-0.262 0.262" actuatorfrcrange="-140 140"/>
                  <geom name="left_ankle_roll_link_visual_0" class="vr_h3_1_visual" quat="0 0.707107 0 0.707107" type="mesh" mesh="left_ankle_roll_link"/>
                  <geom name="left_ankle_roll_link_collision_1" class="vr_h3_1_collision" size="0.014969 0.038005 0.039147" pos="0.130397 0 0.010702" quat="0 0.707107 0 0.707107" type="box"/>
                  <geom name="left_ankle_roll_link_collision_2" class="vr_h3_1_collision" size="0.014969 0.036005 0.009147" pos="-0.051815 0 0.010702" quat="0 0.707107 0 0.707107" type="box"/>
                  <geom name="left_ankle_roll_link_collision_3" class="vr_h3_1_collision" size="0.010969 0.022005 0.01" pos="0.186905 -0.005512 -0.015237" quat="0 0.707107 0 0.707107" type="box"/>
                  <geom name="left_ankle_roll_link_collision_4" class="vr_h3_1_collision" size="0.010969 0.045005 0.112147" pos="0.064757 0 -0.015237" quat="0 0.707107 0 0.707107" type="box"/>
                  <geom name="left_ankle_roll_link_collision_5" class="vr_h3_1_collision" size="0.010969 0.028005 0.008147" pos="-0.055537 0.004563 -0.015237" quat="0 0.707107 0 0.707107" type="box"/>
                  <geom name="left_ankle_roll_link_collision_6" class="vr_h3_1_collision" size="0.005" pos="0.195892 -0.005 -0.035" quat="0 0.707107 0 0.707107"/>
                  <geom name="left_ankle_roll_link_collision_7" class="vr_h3_1_collision" size="0.005" pos="0.11662 -0.05 -0.035" quat="0 0.707107 0 0.707107"/>
                  <geom name="left_ankle_roll_link_collision_8" class="vr_h3_1_collision" size="0.005" pos="0.11662 0.045 -0.035" quat="0 0.707107 0 0.707107"/>
                  <geom name="left_ankle_roll_link_collision_9" class="vr_h3_1_collision" size="0.005" pos="-0.055879 -0.023 -0.035" quat="0 0.707107 0 0.707107"/>
                  <geom name="left_ankle_roll_link_collision_10" class="vr_h3_1_collision" size="0.005" pos="-0.055879 0.025 -0.035" quat="0 0.707107 0 0.707107"/>
                </body>
              </body>
            </body>
          </body>
        </body>
      </body>
      <body name="right_hip_pitch_link" pos="0 -0.13345 0">
        <inertial pos="-0.00237 0.00815 0.00015" quat="0.704347 -0.707259 -0.0260834 -0.0547786" mass="3.46394" diaginertia="0.0050098 0.0056898 0.006817"/>
        <joint name="right_hip_pitch_joint" pos="0 0 0" axis="0 1 0" range="-1.571 0.436" actuatorfrcrange="-369 369"/>
        <geom name="right_hip_pitch_link_visual_0" class="vr_h3_1_visual" quat="0.5 -0.5 0.5 0.5" type="mesh" mesh="right_hip_pitch_link"/>
        <body name="right_hip_roll_link">
          <inertial pos="-0.05315 -0.00019 -0.05534" quat="-0.640916 0.639759 0.300502 0.299386" mass="5.4108" diaginertia="0.0115051 0.0434191 0.0468964"/>
          <joint name="right_hip_roll_joint" pos="0 0 0" axis="1 0 0" range="-1.047 0.175" actuatorfrcrange="-369 369"/>
          <geom name="right_hip_roll_link_visual_0" class="vr_h3_1_visual" quat="0.5 0.5 0.5 0.5" type="mesh" mesh="right_hip_roll_link"/>
          <geom name="right_hip_roll_link_collision_1" class="vr_h3_1_collision" size="0.065701 0.094456 0.089701" pos="0 0 -0.074544" quat="0.5 0.5 0.5 0.5" type="box"/>
          <geom name="right_hip_roll_link_collision_2" class="vr_h3_1_collision" size="0.065701 0.065701 0.03" pos="-0.119701 0 -0.000506" quat="0.5 0.5 0.5 0.5" type="box"/>
          <body name="right_hip_yaw_link" pos="0 0 -0.163">
            <inertial pos="0.00114 -0.00594 -0.16274" quat="0.491997 0.499747 -0.523649 0.483718" mass="4.22238" diaginertia="0.0064746 0.0187543 0.019897"/>
            <joint name="right_hip_yaw_joint" pos="0 0 0" axis="0 0 1" range="-0.785 0.785" actuatorfrcrange="-191 191"/>
            <geom name="right_hip_yaw_link_visual_0" class="vr_h3_1_visual" pos="0 0 -0.19" quat="0 0 0 1" type="mesh" mesh="right_hip_yaw_link"/>
            <geom name="right_hip_yaw_link_collision_1" class="vr_h3_1_collision" size="0.064107 0.064107 0.028465" pos="0 0 -0.04" quat="0 0 0 1" type="box"/>
            <body name="right_knee_pitch_link" pos="0 0 -0.19">
              <inertial pos="-0.0093 -0.00077 -0.17313" quat="-0.710539 0.0218302 0.703086 0.0180948" mass="4.51562" diaginertia="0.0081351 0.0536579 0.0545146"/>
              <joint name="right_knee_pitch_joint" pos="0 0 0" axis="0 1 0" range="-0.175 2.094" actuatorfrcrange="-369 369"/>
              <geom name="right_knee_pitch_link_visual_0" class="vr_h3_1_visual" pos="0 0 0" quat="-0.5 0.5 0.5 0.5" type="mesh" mesh="right_knee_pitch_link"/>
              <geom name="right_knee_pitch_link_collision_1" class="vr_h3_1_collision" size="0.091441 0.055441 0.057441" pos="-0.008043 0 -0.031032" quat="-0.5 0.5 0.5 0.5" type="box"/>
              <geom name="right_knee_pitch_link_collision_2" class="vr_h3_1_collision" size="0.069441 0.069441 0.059441" pos="-0.018343 0 -0.191913" quat="-0.5 0.5 0.5 0.5" type="box"/>
              <geom name="right_knee_pitch_link_collision_3" class="vr_h3_1_collision" size="0.059441 0.050441 0.052441" pos="-0.002033 0 -0.320795" quat="-0.5 0.5 0.5 0.5" type="box"/>
              <body name="right_ankle_pitch_link" pos="0 0 -0.434">
                <inertial pos="-0.00032 0 -0.00762" quat="0.462223 -0.463154 0.534435 0.534993" mass="0.08624" diaginertia="0.0000132 0.0000165 0.0000179"/>
                <joint name="right_ankle_pitch_joint" pos="0 0 0" axis="0 1 0" range="-0.873 0.524" actuatorfrcrange="-140 140"/>
                <geom name="right_ankle_pitch_link_visual_0" class="vr_h3_1_visual" quat="-0.5 0.5 0.5 0.5" type="mesh" mesh="right_ankle_pitch_link"/>
                <body name="right_ankle_roll_link" pos="0 0 -0.014">
                  <inertial pos="0.05279 -0.00065 -0.017" quat="0.999729 -0.0043234 -0.0181868 0.0138545" mass="1.15735" diaginertia="0.0010949 0.0054005 0.0059189"/>
                  <joint name="right_ankle_roll_joint" pos="0 0 0" axis="1 0 0" range="-0.262 0.262" actuatorfrcrange="-140 140"/>
                  <geom name="right_ankle_roll_link_visual_0" class="vr_h3_1_visual" quat="0 0.707107 0 0.707107" type="mesh" mesh="right_ankle_roll_link"/>
                  <geom name="right_ankle_roll_link_collision_1" class="vr_h3_1_collision" size="0.014969 0.038005 0.039147" pos="0.130397 0 0.010702" quat="0 0.707107 0 0.707107" type="box"/>
                  <geom name="right_ankle_roll_link_collision_2" class="vr_h3_1_collision" size="0.014969 0.036005 0.009147" pos="-0.051815 0 0.010702" quat="0 0.707107 0 0.707107" type="box"/>
                  <geom name="right_ankle_roll_link_collision_3" class="vr_h3_1_collision" size="0.010969 0.022005 0.01" pos="0.186905 0.005512 -0.015237" quat="0 0.707107 0 0.707107" type="box"/>
                  <geom name="right_ankle_roll_link_collision_4" class="vr_h3_1_collision" size="0.010969 0.045005 0.112147" pos="0.064757 0 -0.015237" quat="0 0.707107 0 0.707107" type="box"/>
                  <geom name="right_ankle_roll_link_collision_5" class="vr_h3_1_collision" size="0.010969 0.028005 0.008147" pos="-0.055537 -0.004563 -0.015237" quat="0 0.707107 0 0.707107" type="box"/>
                  <geom name="right_ankle_roll_link_collision_6" class="vr_h3_1_collision" size="0.005" pos="0.195892 0.005 -0.035" quat="0 0.707107 0 0.707107"/>
                  <geom name="right_ankle_roll_link_collision_7" class="vr_h3_1_collision" size="0.005" pos="0.11662 0.05 -0.035" quat="0 0.707107 0 0.707107"/>
                  <geom name="right_ankle_roll_link_collision_8" class="vr_h3_1_collision" size="0.005" pos="0.11662 -0.045 -0.035" quat="0 0.707107 0 0.707107"/>
                  <geom name="right_ankle_roll_link_collision_9" class="vr_h3_1_collision" size="0.005" pos="-0.055879 0.023 -0.035" quat="0 0.707107 0 0.707107"/>
                  <geom name="right_ankle_roll_link_collision_10" class="vr_h3_1_collision" size="0.005" pos="-0.055879 -0.025 -0.035" quat="0 0.707107 0 0.707107"/>
                </body>
              </body>
            </body>
          </body>
        </body>
      </body>
      <body name="waist_yaw_link" pos="0 0 0.151">
        <inertial pos="-0.0064 -0.00001 -0.00609" quat="0.697055 -0.69717 -0.118459 -0.118472" mass="1.97052" diaginertia="0.0023392 0.0025432 0.0028637"/>
        <joint name="waist_yaw_joint" pos="0 0 0" axis="0 0 1" range="-2.618 2.618" actuatorfrcrange="-102 102"/>
        <geom name="waist_yaw_link_visual_0" class="vr_h3_1_visual" quat="0.707107 0 0 0.707107" type="mesh" mesh="waist_yaw_link"/>
        <body name="waist_roll_link">
          <inertial pos="-0.03119 0.0007 0.23753" quat="-0.671962 0.0043036 0.740562 -0.0042061" mass="22.2137" diaginertia="0.209579 0.393069 0.462874"/>
          <!-- <joint name="waist_roll_joint" pos="0 0 0" axis="1 0 0" range="-0.262 0.262" actuatorfrcrange="-102 102"/> -->
          <geom name="waist_roll_link_visual_0" class="vr_h3_1_visual" pos="0 0 0" quat="0 0.707107 0 0.707107" type="mesh" mesh="waist_roll_link"/>
          <geom name="waist_roll_link_collision_1" class="vr_h3_1_collision" size="0.05 0.145 0.1" pos="-0.002 0 0.38" quat="0 0.707107 0 0.707107" type="box"/>
          <geom name="waist_roll_link_collision_2" class="vr_h3_1_collision" size="0.1 0.151 0.124" pos="-0.002 0 0.23" quat="0 0.707107 0 0.707107" type="box"/>
          <geom name="waist_roll_link_collision_3" class="vr_h3_1_collision" size="0.05 0.145 0.12" pos="-0.005 0 0.08" quat="0 0.707107 0 0.707107" type="box"/>
          <body name="left_shoulder_pitch_link" pos="0 0.2075 0.36753">
            <inertial pos="-0.00489 -0.0021666 -0.0000183" quat="0.551393 -0.28526 -0.450542 0.641564" mass="1.02367" diaginertia="0.0008954 0.0009779 0.0010043"/>
            <joint name="left_shoulder_pitch_joint" pos="0 0 0" axis="0 0.996219 0.0868828" range="-3.14 1.047" actuatorfrcrange="-66 66"/>
            <geom name="left_shoulder_pitch_link_visual_0" class="vr_h3_1_visual" quat="0.521268 -0.477786 0.477786 0.521268" type="mesh" mesh="left_shoulder_pitch_link"/>
            <body name="left_shoulder_roll_link" pos="-0.009 0 0">
              <inertial pos="0.00046 0.0000202 -0.09827" quat="0.500502 0.504283 0.49799 -0.497195" mass="1.19875" diaginertia="0.0013096 0.0026266 0.0027416"/>
              <joint name="left_shoulder_roll_joint" pos="0 0 0" axis="1 0 0" range="0 2.356" actuatorfrcrange="-66 66"/>
              <geom name="left_shoulder_roll_link_visual_0" class="vr_h3_1_visual" quat="0.500076 0.499924 0.500076 0.499924" type="mesh" mesh="left_shoulder_roll_link"/>
              <geom name="left_shoulder_roll_link_collision_1" class="vr_h3_1_collision" size="0.04 0.07 0.04" pos="0 -0.0000206 -0.068" quat="0.500076 0.499924 0.500076 0.499924" type="box"/>
              <body name="left_shoulder_yaw_link" pos="0 -0.0000758 -0.25">
                <inertial pos="-0.00499 -0.0147933 0.0550945" quat="0.548317 -0.446329 0.309129 0.636065" mass="0.29744" diaginertia="0.0002575 0.0006384 0.0006648"/>
                <joint name="left_shoulder_yaw_joint" pos="0 0 0" axis="0 0.0003032 1" range="-2.967 2.967" actuatorfrcrange="-66 66"/>
                <geom name="left_shoulder_yaw_link_visual_0" class="vr_h3_1_visual" quat="0 0 0.0001516 1" type="mesh" mesh="left_shoulder_yaw_link"/>
                <geom name="left_shoulder_yaw_link_collision_1" class="vr_h3_1_collision" size="0.038896 0.038896 0.015" pos="0 0.0000284 0.093834" quat="0 0 0.0001516 1" type="box"/>
                <geom name="left_shoulder_yaw_link_collision_2" class="vr_h3_1_collision" size="0.022896 0.038896 0.016933" pos="-0.016 0.0000197 0.064901" quat="0 0 0.0001516 1" type="box"/>
                <body name="left_elbow_pitch_link">
                  <inertial pos="0.04407 0.00163 -0.0000605" quat="-0.0102348 -0.0110786 0.712544 0.701465" mass="1.59951" diaginertia="0.0013069 0.005226 0.0052862"/>
                  <joint name="left_elbow_pitch_joint" pos="0 0 0" axis="0 1 -0.0003032" range="-0.524 1.571" actuatorfrcrange="-66 66"/>
                  <geom name="left_elbow_pitch_link_visual_0" class="vr_h3_1_visual" pos="0 0 0" quat="-0.499924 0.500076 0.500076 0.499924" type="mesh" mesh="left_elbow_pitch_link"/>
                  <geom name="left_elbow_pitch_link_collision_1" class="vr_h3_1_collision" size="0.041004 0.041004 0.041004" pos="0.096 0 0" quat="-0.499924 0.500076 0.500076 0.499924" type="box"/>
                  <body name="left_wrist_yaw_link" pos="0.247 0 0">
                    <inertial pos="-0.06275 0 -0.00151" quat="-0.706905 0.707139 0.0109235 0.0109581" mass="0.63403" diaginertia="0.0005751 0.0007938 0.0009662"/>
                    <joint name="left_wrist_yaw_joint" pos="0 0 0" axis="-1 0 0" range="-2.967 2.967" actuatorfrcrange="-34 34"/>
                    <geom name="left_wrist_yaw_link_visual_0" class="vr_h3_1_visual" quat="-0.499924 0.500076 0.499924 -0.500076" type="mesh" mesh="left_wrist_yaw_link"/>
                    <geom name="left_wrist_yaw_link_collision_1" class="vr_h3_1_collision" size="0.041004 0.041004 0.025729" pos="-0.077271 0 0" quat="-0.499924 0.500076 0.499924 -0.500076" type="box"/>
                    <body name="left_wrist_roll_link">
                      <inertial pos="0.00982 0.00219 0" quat="0.486545 0.501913 -0.519685 -0.491207" mass="0.4084" diaginertia="0.0001904 0.000242 0.0002487"/>
                      <joint name="left_wrist_roll_joint" pos="0 0 0" axis="0 0.0003032 1" range="-1.134 0.698" actuatorfrcrange="-11 11"/>
                      <geom name="left_wrist_roll_link_visual_0" class="vr_h3_1_visual" quat="0 0 -0.0001516 -1" type="mesh" mesh="left_wrist_roll_link"/>
                      <geom name="left_wrist_roll_link_collision_1" class="vr_h3_1_collision" size="0.029 0.032 0.029" pos="0.01 0 0" quat="0 0 -0.0001516 -1" type="box"/>
                      <body name="left_wrist_pitch_link" pos="0.01 0 0">
                        <inertial pos="0.03141 0.0184 0.0000044" quat="0.273977 0.272915 -0.651105 -0.653082" mass="0.14968" diaginertia="0.0000445 0.0001146 0.0001243"/>
                        <joint name="left_wrist_pitch_joint" pos="0 0 0" axis="0 1 -0.0003032" range="-0.96 0.96" actuatorfrcrange="-11 11"/>
                        <geom name="left_wrist_pitch_link_visual_0" class="vr_h3_1_visual" pos="0 0 0" quat="0 0 -0.707214 -0.707" type="mesh" mesh="left_wrist_pitch_link"/>
                        <geom name="left_wrist_pitch_link_collision_1" class="vr_h3_1_collision" size="0.002399 0.033058 0.025221" pos="0.04441 0.005139 0" quat="0 0 -0.707214 -0.707" type="box"/>
                        <geom name="left_wrist_pitch_link_collision_2" class="vr_h3_1_collision" size="0.023399 0.022016 0.004221" pos="0.01 0.038911 -0.0000118" quat="0 0 -0.707214 -0.707" type="box"/>
                      </body>
                    </body>
                  </body>
                </body>
              </body>
            </body>
          </body>
          <body name="right_shoulder_pitch_link" pos="0 -0.2075 0.36753">
            <inertial pos="-0.00489 0.0021666 -0.0000183" quat="0.28526 -0.551393 0.641564 -0.450542" mass="1.02367" diaginertia="0.0008954 0.0009779 0.0010043"/>
            <joint name="right_shoulder_pitch_joint" pos="0 0 0" axis="0 0.996219 -0.0868828" range="-3.14 1.047" actuatorfrcrange="-66 66"/>
            <geom name="right_shoulder_pitch_link_visual_0" class="vr_h3_1_visual" quat="0.477786 -0.521268 0.521268 0.477786" type="mesh" mesh="right_shoulder_pitch_link"/>
            <body name="right_shoulder_roll_link" pos="-0.009 0 0">
              <inertial pos="0.00046 -0.0000202 -0.09827" quat="0.497195 -0.49799 -0.504283 -0.500502" mass="1.19875" diaginertia="0.0013096 0.0026266 0.0027416"/>
              <joint name="right_shoulder_roll_joint" pos="0 0 0" axis="1 0 0" range="-2.356 0" actuatorfrcrange="-66 66"/>
              <geom name="right_shoulder_roll_link_visual_0" class="vr_h3_1_visual" quat="-0.499924 -0.500076 -0.499924 -0.500076" type="mesh" mesh="right_shoulder_roll_link"/>
              <geom name="right_shoulder_roll_link_collision_1" class="vr_h3_1_collision" size="0.04 0.07 0.04" pos="0 0.0000206 -0.068" quat="-0.499924 -0.500076 -0.499924 -0.500076" type="box"/>
              <body name="right_shoulder_yaw_link" pos="0 0.0000758 -0.25">
                <inertial pos="-0.00499 -0.0148267 0.0550855" quat="-0.542472 0.453095 -0.305981 -0.637812" mass="0.29744" diaginertia="0.0002547 0.00063 0.0006579"/>
                <joint name="right_shoulder_yaw_joint" pos="0 0 0" axis="0 -0.0003032 1" range="-2.967 2.967" actuatorfrcrange="-66 66"/>
                <geom name="right_shoulder_yaw_link_visual_0" class="vr_h3_1_visual" quat="0 0 0.0001516 -1" type="mesh" mesh="right_shoulder_yaw_link"/>
                <geom name="right_shoulder_yaw_link_collision_1" class="vr_h3_1_collision" size="0.038896 0.038896 0.015" pos="0 -0.0000284 0.093834" quat="0 0 0.0001516 -1" type="box"/>
                <geom name="right_shoulder_yaw_link_collision_2" class="vr_h3_1_collision" size="0.022896 0.038896 0.016933" pos="-0.016 -0.0000197 0.064901" quat="0 0 0.0001516 -1" type="box"/>
                <body name="right_elbow_pitch_link">
                  <inertial pos="0.04407 0.00163 -0.0000395" quat="-0.712238 -0.701775 -0.0105773 -0.0108035" mass="1.59951" diaginertia="0.0013069 0.005226 0.0052863"/>
                  <joint name="right_elbow_pitch_joint" pos="0 0 0" axis="0 1 0.0003032" range="-0.524 1.571" actuatorfrcrange="-66 66"/>
                  <geom name="right_elbow_pitch_link_visual_0" class="vr_h3_1_visual" pos="0 0 0" quat="0.500076 -0.499924 -0.499924 -0.500076" type="mesh" mesh="right_elbow_pitch_link"/>
                  <geom name="right_elbow_pitch_link_collision_1" class="vr_h3_1_collision" size="0.041004 0.041004 0.041004" pos="0.096 0 0" quat="0.500076 -0.499924 -0.499924 -0.500076" type="box"/>
                  <body name="right_wrist_yaw_link" pos="0.247 0 0">
                    <inertial pos="-0.06275 0 0.00151" quat="0.0109615 -0.0109201 -0.706925 -0.707119" mass="0.63403" diaginertia="0.0005751 0.0007938 0.0009662"/>
                    <joint name="right_wrist_yaw_joint" pos="0 0 0" axis="-1 0 0" range="-2.967 2.967" actuatorfrcrange="-34 34"/>
                    <geom name="right_wrist_yaw_link_visual_0" class="vr_h3_1_visual" quat="0.500076 -0.499924 -0.500076 0.499924" type="mesh" mesh="right_wrist_yaw_link"/>
                    <geom name="right_wrist_yaw_link_collision_1" class="vr_h3_1_collision" size="0.041004 0.041004 0.025729" pos="-0.077271 0 0" quat="0.500076 -0.499924 -0.500076 0.499924" type="box"/>
                    <body name="right_wrist_roll_link">
                      <inertial pos="0.00982 -0.00219 0" quat="-0.519536 -0.491365 0.486393 0.502061" mass="0.4084" diaginertia="0.0001904 0.0002421 0.0002487"/>
                      <joint name="right_wrist_roll_joint" pos="0 0 0" axis="0 -0.0003032 1" range="-0.698 1.134" actuatorfrcrange="-11 11"/>
                      <geom name="right_wrist_roll_link_visual_0" class="vr_h3_1_visual" quat="0 0 -0.0001516 1" type="mesh" mesh="right_wrist_roll_link"/>
                      <geom name="right_wrist_roll_link_collision_1" class="vr_h3_1_collision" size="0.029 0.032 0.029" pos="0.01 0 0" quat="0 0 -0.0001516 1" type="box"/>
                      <body name="right_wrist_pitch_link" pos="0.01 0 0">
                        <inertial pos="0.03141 -0.0184 0.0000044" quat="0.272915 0.273977 0.653082 0.651105" mass="0.14968" diaginertia="0.0000445 0.0001146 0.0001243"/>
                        <joint name="right_wrist_pitch_joint" pos="0 0 0" axis="0 1 0.0003032" range="-0.96 0.96" actuatorfrcrange="-11 11"/>
                        <geom name="right_wrist_pitch_link_visual_0" class="vr_h3_1_visual" quat="0 0 0.707 0.707214" type="mesh" mesh="right_wrist_pitch_link"/>
                        <geom name="right_wrist_pitch_link_collision_1" class="vr_h3_1_collision" size="0.002399 0.033058 0.025221" pos="0.04441 -0.005139 0" quat="0 0 0.707 0.707214" type="box"/>
                        <geom name="right_wrist_pitch_link_collision_2" class="vr_h3_1_collision" size="0.023399 0.022016 0.004221" pos="0.01 -0.038911 -0.0000118" quat="0 0 0.707 0.707214" type="box"/>
                      </body>
                    </body>
                  </body>
                </body>
              </body>
            </body>
          </body>
          <body name="head_yaw_link" pos="-0.015 0 0.5881">
            <inertial pos="-0.00099 0.00538 -0.0318" quat="-0.0560424 0.703068 -0.021687 0.70858" mass="0.74204" diaginertia="0.0005898 0.0017361 0.0018211"/>
            <!-- <joint name="head_yaw_joint" pos="0 0 0" axis="0 0 1" range="-1.571 1.571" actuatorfrcrange="-11 11"/> -->
            <geom name="head_yaw_link_visual_0" class="vr_h3_1_visual" quat="-1 0 0 0" type="mesh" mesh="head_yaw_link"/>
            <body name="head_pitch_link">
              <inertial pos="0.03262 -0.0005 0.01482" quat="-0.0986943 -0.0143738 -0.988032 0.117663" mass="0.88663" diaginertia="0.0037466 0.0052497 0.0053012"/>
              <!-- <joint name="head_pitch_joint" pos="0 0 0" axis="0 1 0" range="-0.262 0.436" actuatorfrcrange="-4.8 4.8"/> -->
              <geom name="head_pitch_link_visual_0" class="vr_h3_1_visual" quat="0 0 -0.707107 -0.707107" type="mesh" mesh="head_pitch_link"/>
              <geom name="head_pitch_link_collision_1" class="vr_h3_1_collision" size="0.110093 0.077614 0.082732" pos="0.025672 0 0.02359" quat="0 0 -0.707107 -0.707107" type="box"/>
              <geom name="head_pitch_link_collision_2" class="vr_h3_1_collision" size="0.041132 0.021736 0.06016" pos="0.08504 0 -0.07576" quat="0 0 -0.707107 -0.707107" type="box"/>
            </body>
          </body>
        </body>
      </body>
    </body>
  </worldbody>
  <include file="vr_h3_1_sensors.xml"/>
</mujoco>
